bioimageio_core_version: 0.5.3.post2
bioimageio_spec_version: 0.4.5.post4
rdf_sha256: e00744886e03b8c48ae1c6816e3be730ec910402acd10a5f425e20692bd77785
status: passed
tests:
  bioimageio:
  - bioimageio_spec_version: 0.4.5post4
    error: null
    name: bioimageio.spec static validation of model RDF 0.4.5 with update to latest
      format version
    nested_errors: {}
    status: passed
    traceback: null
    warnings: {tags: 'Missing tags for categories: [{''framework'': [''tensorflow'',
        ''pytorch'', ''tensorflow.js'']}, {''task'': [''semantic-segmentation'', ''instance-segmentation'',
        ''object-detection'', ''image-classification'', ''denoising'', ''image-restoration'',
        ''image-reconstruction'', ''in-silico-labeling'']}]'}
  - bioimageio_spec_version: 0.4.5post4
    error: null
    name: bioimageio.spec static validation of model RDF 0.4.5
    nested_errors: {}
    status: passed
    traceback: null
    warnings: {tags: 'Missing tags for categories: [{''framework'': [''tensorflow'',
        ''pytorch'', ''tensorflow.js'']}, {''task'': [''semantic-segmentation'', ''instance-segmentation'',
        ''object-detection'', ''image-classification'', ''denoising'', ''image-restoration'',
        ''image-reconstruction'', ''in-silico-labeling'']}]'}
  - {bioimageio_core_version: 0.5.3post2, bioimageio_spec_version: 0.4.5post4, error: null,
    name: reproduced test outputs from test inputs, status: passed, traceback: null}
  ilastik:
  - bioimageio_core_version: 0.5.1
    bioimageio_spec_version: 0.4.5post3
    error: '''str'' object has no attribute ''decode'''
    name: reproduce test outputs with ilastik <todo version> (draft) using keras_hdf5
      weights
    reason: error
    status: failed
    traceback: ["  File \"/usr/share/miniconda3/envs/ilastik-env/lib/python3.7/site-packages/bioimageio/core/resource_tests.py\",
        line 148, in test_resource\n    bioimageio_model=model, devices=devices, weight_format=weight_format\n",
      "  File \"/usr/share/miniconda3/envs/ilastik-env/lib/python3.7/site-packages/bioimageio/core/prediction_pipeline/_prediction_pipeline.py\",
        line 103, in __enter__\n    self.load()\n", "  File \"/usr/share/miniconda3/envs/ilastik-env/lib/python3.7/site-packages/bioimageio/core/prediction_pipeline/_prediction_pipeline.py\",
        line 143, in load\n    self._model.load()\n", "  File \"/usr/share/miniconda3/envs/ilastik-env/lib/python3.7/site-packages/bioimageio/core/prediction_pipeline/_model_adapters/_model_adapter.py\",
        line 41, in load\n    self._load(devices=devices or self.default_devices)\n",
      "  File \"/usr/share/miniconda3/envs/ilastik-env/lib/python3.7/site-packages/bioimageio/core/prediction_pipeline/_model_adapters/_keras_model_adapter.py\",
        line 39, in _load\n    self._model = keras.models.load_model(weight_file)\n",
      "  File \"/usr/share/miniconda3/envs/ilastik-env/lib/python3.7/site-packages/tensorflow/python/keras/saving/save.py\",
        line 146, in load_model\n    return hdf5_format.load_model_from_hdf5(filepath,
        custom_objects, compile)\n", "  File \"/usr/share/miniconda3/envs/ilastik-env/lib/python3.7/site-packages/tensorflow/python/keras/saving/hdf5_format.py\",
        line 210, in load_model_from_hdf5\n    model_config = json.loads(model_config.decode('utf-8'))\n"]
  - bioimageio_core_version: 0.5.3post2
    bioimageio_spec_version: 0.4.5post6
    error: No module named 'tensorflow'
    name: reproduce test outputs with ilastik <todo version> (draft) using keras_hdf5
      weights
    reason: error
    status: failed
    traceback: ["  File \"/home/runner/.local/lib/python3.8/site-packages/bioimageio/core/resource_tests.py\",
        line 147, in test_resource\n    with create_prediction_pipeline(\n", "  File
        \"/home/runner/.local/lib/python3.8/site-packages/bioimageio/core/prediction_pipeline/_prediction_pipeline.py\",
        line 195, in create_prediction_pipeline\n    model_adapter: ModelAdapter =
        create_model_adapter(\n", "  File \"/home/runner/.local/lib/python3.8/site-packages/bioimageio/core/prediction_pipeline/_model_adapters/_model_adapter.py\",
        line 113, in create_model_adapter\n    adapter_cls = _get_model_adapter(weight)\n",
      "  File \"/home/runner/.local/lib/python3.8/site-packages/bioimageio/core/prediction_pipeline/_model_adapters/_model_adapter.py\",
        line 154, in _get_model_adapter\n    from ._tensorflow_model_adapter import
        KerasModelAdapter\n", "  File \"/home/runner/.local/lib/python3.8/site-packages/bioimageio/core/prediction_pipeline/_model_adapters/_tensorflow_model_adapter.py\",
        line 6, in <module>\n    import tensorflow as tf\n"]
  - bioimageio_core_version: 0.5.3post2
    bioimageio_spec_version: 0.4.5post6
    error: No module named 'tensorflow'
    name: reproduce test outputs with ilastik <todo version> (draft) using tensorflow_saved_model_bundle
      weights
    reason: error
    status: failed
    traceback: ["  File \"/home/runner/.local/lib/python3.8/site-packages/bioimageio/core/resource_tests.py\",
        line 147, in test_resource\n    with create_prediction_pipeline(\n", "  File
        \"/home/runner/.local/lib/python3.8/site-packages/bioimageio/core/prediction_pipeline/_prediction_pipeline.py\",
        line 195, in create_prediction_pipeline\n    model_adapter: ModelAdapter =
        create_model_adapter(\n", "  File \"/home/runner/.local/lib/python3.8/site-packages/bioimageio/core/prediction_pipeline/_model_adapters/_model_adapter.py\",
        line 113, in create_model_adapter\n    adapter_cls = _get_model_adapter(weight)\n",
      "  File \"/home/runner/.local/lib/python3.8/site-packages/bioimageio/core/prediction_pipeline/_model_adapters/_model_adapter.py\",
        line 133, in _get_model_adapter\n    from ._tensorflow_model_adapter import
        TensorflowModelAdapter\n", "  File \"/home/runner/.local/lib/python3.8/site-packages/bioimageio/core/prediction_pipeline/_model_adapters/_tensorflow_model_adapter.py\",
        line 6, in <module>\n    import tensorflow as tf\n"]
  - {bioimageio_core_version: 0.5.1, bioimageio_spec_version: 0.4.5post3, error: null,
    name: reproduce test outputs with ilastik <todo version> (draft) using tensorflow_saved_model_bundle
      weights, reason: null, status: passed, traceback: null}
