bioimageio_core_version: 0.5.3.post2
bioimageio_spec_version: 0.4.5.post11
rdf_sha256: e00744886e03b8c48ae1c6816e3be730ec910402acd10a5f425e20692bd77785
status: passed
tests:
  bioimageio:
  - bioimageio_spec_version: 0.4.5post11
    error: null
    name: bioimageio.spec static validation of model RDF 0.4.5 with update to latest
      format version
    nested_errors: {}
    status: passed
    traceback: null
    warnings: {tags: 'Missing tags for categories: [{''framework'': [''tensorflow'',
        ''pytorch'', ''tensorflow.js'']}, {''task'': [''semantic-segmentation'', ''instance-segmentation'',
        ''object-detection'', ''image-classification'', ''denoising'', ''image-restoration'',
        ''image-reconstruction'', ''in-silico-labeling'']}]'}
  - bioimageio_spec_version: 0.4.5post11
    error: null
    name: bioimageio.spec static validation of model RDF 0.4.5
    nested_errors: {}
    status: passed
    traceback: null
    warnings: {tags: 'Missing tags for categories: [{''framework'': [''tensorflow'',
        ''pytorch'', ''tensorflow.js'']}, {''task'': [''semantic-segmentation'', ''instance-segmentation'',
        ''object-detection'', ''image-classification'', ''denoising'', ''image-restoration'',
        ''image-reconstruction'', ''in-silico-labeling'']}]'}
  - {bioimageio_core_version: 0.5.3post2, bioimageio_spec_version: 0.4.5post11, error: null,
    name: reproduced test outputs from test inputs, status: passed, traceback: null}
  deepimagej:
  - {bioimageio_spec_version: 0.4.8post1, error: Sample image tiffs have not been
      generated from numpy tests files, name: Initial compatibility checks with DeepImageJ,
    status: failed}
  ilastik:
  - bioimageio_core_version: 0.5.8
    bioimageio_spec_version: 0.4.9
    error: null
    name: load resource description
    nested_errors: null
    status: passed
    traceback: null
    warnings: {}
  - {error: null, name: has expected resource type, status: passed, traceback: null}
  - bioimageio_core_version: 0.5.8
    bioimageio_spec_version: 0.4.9
    error: null
    name: All URLs and paths available
    nested_errors: null
    status: passed
    traceback: null
    warnings: {}
  - bioimageio_core_version: 0.5.8
    bioimageio_spec_version: 0.4.9
    error: null
    name: Test documentation completeness.
    status: passed
    traceback: null
    warnings: {documentation: No '# Validation' (sub)section found.}
  - bioimageio_core_version: 0.5.8
    bioimageio_spec_version: 0.4.9
    error: null
    name: reproduce test outputs from test inputs
    status: passed
    traceback: null
    warnings:
      non-validation-warnings: ['Device management is not implemented for keras yet,
          cannot unload model', 'Model tensorflow version (1, 15) does not match 1.14.0.The
          prediction results may be wrong', Computed dataset percentiles naively by
          averaging percentiles of samples.]
  - bioimageio_core_version: 0.5.1
    bioimageio_spec_version: 0.4.5post3
    error: '''str'' object has no attribute ''decode'''
    name: reproduce test outputs with ilastik 1.4.0b26 using keras_hdf5 weights
    reason: error
    status: failed
    traceback: ["  File \"/usr/share/miniconda3/envs/ilastik-env/lib/python3.7/site-packages/bioimageio/core/resource_tests.py\",
        line 148, in test_resource\n    bioimageio_model=model, devices=devices, weight_format=weight_format\n",
      "  File \"/usr/share/miniconda3/envs/ilastik-env/lib/python3.7/site-packages/bioimageio/core/prediction_pipeline/_prediction_pipeline.py\",
        line 103, in __enter__\n    self.load()\n", "  File \"/usr/share/miniconda3/envs/ilastik-env/lib/python3.7/site-packages/bioimageio/core/prediction_pipeline/_prediction_pipeline.py\",
        line 143, in load\n    self._model.load()\n", "  File \"/usr/share/miniconda3/envs/ilastik-env/lib/python3.7/site-packages/bioimageio/core/prediction_pipeline/_model_adapters/_model_adapter.py\",
        line 41, in load\n    self._load(devices=devices or self.default_devices)\n",
      "  File \"/usr/share/miniconda3/envs/ilastik-env/lib/python3.7/site-packages/bioimageio/core/prediction_pipeline/_model_adapters/_keras_model_adapter.py\",
        line 39, in _load\n    self._model = keras.models.load_model(weight_file)\n",
      "  File \"/usr/share/miniconda3/envs/ilastik-env/lib/python3.7/site-packages/tensorflow/python/keras/saving/save.py\",
        line 146, in load_model\n    return hdf5_format.load_model_from_hdf5(filepath,
        custom_objects, compile)\n", "  File \"/usr/share/miniconda3/envs/ilastik-env/lib/python3.7/site-packages/tensorflow/python/keras/saving/hdf5_format.py\",
        line 210, in load_model_from_hdf5\n    model_config = json.loads(model_config.decode('utf-8'))\n"]
  - bioimageio_core_version: 0.5.3post2
    bioimageio_spec_version: 0.4.5post6
    error: '''str'' object has no attribute ''decode'''
    name: reproduce test outputs with ilastik 1.4.0b27 using keras_hdf5 weights
    reason: error
    status: failed
    traceback: ["  File \"/usr/share/miniconda3/envs/ilastik-env/lib/python3.7/site-packages/bioimageio/core/resource_tests.py\",
        line 148, in test_resource\n    bioimageio_model=model, devices=devices, weight_format=weight_format\n",
      "  File \"/usr/share/miniconda3/envs/ilastik-env/lib/python3.7/site-packages/bioimageio/core/prediction_pipeline/_prediction_pipeline.py\",
        line 114, in __enter__\n    self.load()\n", "  File \"/usr/share/miniconda3/envs/ilastik-env/lib/python3.7/site-packages/bioimageio/core/prediction_pipeline/_prediction_pipeline.py\",
        line 172, in load\n    self._model.load()\n", "  File \"/usr/share/miniconda3/envs/ilastik-env/lib/python3.7/site-packages/bioimageio/core/prediction_pipeline/_model_adapters/_model_adapter.py\",
        line 41, in load\n    self._load(devices=devices or self.default_devices)\n",
      "  File \"/usr/share/miniconda3/envs/ilastik-env/lib/python3.7/site-packages/bioimageio/core/prediction_pipeline/_model_adapters/_keras_model_adapter.py\",
        line 41, in _load\n    self._model = keras.models.load_model(weight_file)\n",
      "  File \"/usr/share/miniconda3/envs/ilastik-env/lib/python3.7/site-packages/tensorflow/python/keras/saving/save.py\",
        line 146, in load_model\n    return hdf5_format.load_model_from_hdf5(filepath,
        custom_objects, compile)\n", "  File \"/usr/share/miniconda3/envs/ilastik-env/lib/python3.7/site-packages/tensorflow/python/keras/saving/hdf5_format.py\",
        line 210, in load_model_from_hdf5\n    model_config = json.loads(model_config.decode('utf-8'))\n"]
  - {bioimageio_core_version: 0.5.3post2, bioimageio_spec_version: 0.4.5post6, error: null,
    name: reproduce test outputs with ilastik 1.4.0b27 using tensorflow_saved_model_bundle
      weights, reason: null, status: passed, traceback: null}
  - {error: Missing/invalid weight formats for 10.5281/zenodo.5817052/5906839, name: reproduce
      test outputs with ilastik 1.4.0b27, reason: error, status: failed}
  - {error: Missing/invalid weight formats for 10.5281/zenodo.5817052/5906839, name: reproduce
      test outputs with ilastik 1.4.0b26, reason: error, status: failed}
  - bioimageio_core_version: 0.5.7
    bioimageio_spec_version: 0.4.8
    error: null
    name: load resource description
    status: passed
    traceback: null
    warnings: {}
  - bioimageio_core_version: 0.5.7
    bioimageio_spec_version: 0.4.8
    error: null
    name: All URLs and paths available
    nested_errors: null
    status: passed
    traceback: null
    warnings: {}
  - bioimageio_core_version: 0.5.7
    bioimageio_spec_version: 0.4.8
    error: null
    name: Test documentation completeness.
    status: passed
    traceback: null
    warnings: {documentation: No '# Validation' (sub)section found.}
  - bioimageio_core_version: 0.5.7
    bioimageio_spec_version: 0.4.8
    error: '''str'' object has no attribute ''decode'''
    name: reproduce test outputs from test inputs
    status: failed
    traceback: ["  File \"/usr/share/miniconda3/envs/ilastik-env/lib/python3.7/site-packages/bioimageio/core/resource_tests.py\",
        line 157, in _test_model_inference\n    bioimageio_model=model, devices=devices,
        weight_format=weight_format\n", "  File \"/usr/share/miniconda3/envs/ilastik-env/lib/python3.7/site-packages/bioimageio/core/prediction_pipeline/_prediction_pipeline.py\",
        line 122, in __enter__\n    self.load()\n", "  File \"/usr/share/miniconda3/envs/ilastik-env/lib/python3.7/site-packages/bioimageio/core/prediction_pipeline/_prediction_pipeline.py\",
        line 180, in load\n    self._model.load()\n", "  File \"/usr/share/miniconda3/envs/ilastik-env/lib/python3.7/site-packages/bioimageio/core/prediction_pipeline/_model_adapters/_model_adapter.py\",
        line 57, in load\n    self._load(devices=devices or self.default_devices)\n",
      "  File \"/usr/share/miniconda3/envs/ilastik-env/lib/python3.7/site-packages/bioimageio/core/prediction_pipeline/_model_adapters/_keras_model_adapter.py\",
        line 41, in _load\n    self._model = keras.models.load_model(weight_file)\n",
      "  File \"/usr/share/miniconda3/envs/ilastik-env/lib/python3.7/site-packages/tensorflow/python/keras/saving/save.py\",
        line 146, in load_model\n    return hdf5_format.load_model_from_hdf5(filepath,
        custom_objects, compile)\n", "  File \"/usr/share/miniconda3/envs/ilastik-env/lib/python3.7/site-packages/tensorflow/python/keras/saving/hdf5_format.py\",
        line 210, in load_model_from_hdf5\n    model_config = json.loads(model_config.decode('utf-8'))\n"]
    warnings:
      non-validation-warnings: ['Model tensorflow version (1, 15) does not match 1.14.0.The
          prediction results may be wrong']
  - {bioimageio_core_version: 0.5.1, bioimageio_spec_version: 0.4.5post3, error: null,
    name: reproduce test outputs with ilastik 1.4.0b26 using tensorflow_saved_model_bundle
      weights, reason: null, status: passed, traceback: null}
  - bioimageio_core_version: 0.5.8
    bioimageio_spec_version: 0.4.9
    error: '''str'' object has no attribute ''decode'''
    name: reproduce test outputs from test inputs
    status: failed
    traceback: ["  File \"/usr/share/miniconda3/envs/ilastik-env/lib/python3.7/site-packages/bioimageio/core/resource_tests.py\",
        line 157, in _test_model_inference\n    bioimageio_model=model, devices=devices,
        weight_format=weight_format\n", "  File \"/usr/share/miniconda3/envs/ilastik-env/lib/python3.7/site-packages/bioimageio/core/prediction_pipeline/_prediction_pipeline.py\",
        line 122, in __enter__\n    self.load()\n", "  File \"/usr/share/miniconda3/envs/ilastik-env/lib/python3.7/site-packages/bioimageio/core/prediction_pipeline/_prediction_pipeline.py\",
        line 180, in load\n    self._model.load()\n", "  File \"/usr/share/miniconda3/envs/ilastik-env/lib/python3.7/site-packages/bioimageio/core/prediction_pipeline/_model_adapters/_model_adapter.py\",
        line 57, in load\n    self._load(devices=devices or self.default_devices)\n",
      "  File \"/usr/share/miniconda3/envs/ilastik-env/lib/python3.7/site-packages/bioimageio/core/prediction_pipeline/_model_adapters/_keras_model_adapter.py\",
        line 41, in _load\n    self._model = keras.models.load_model(weight_file)\n",
      "  File \"/usr/share/miniconda3/envs/ilastik-env/lib/python3.7/site-packages/tensorflow/python/keras/saving/save.py\",
        line 146, in load_model\n    return hdf5_format.load_model_from_hdf5(filepath,
        custom_objects, compile)\n", "  File \"/usr/share/miniconda3/envs/ilastik-env/lib/python3.7/site-packages/tensorflow/python/keras/saving/hdf5_format.py\",
        line 210, in load_model_from_hdf5\n    model_config = json.loads(model_config.decode('utf-8'))\n"]
    warnings:
      non-validation-warnings: ['Model tensorflow version (1, 15) does not match 1.14.0.The
          prediction results may be wrong']
  - bioimageio_core_version: 0.5.7
    bioimageio_spec_version: 0.4.8
    error: null
    name: reproduce test outputs from test inputs
    status: passed
    traceback: null
    warnings:
      non-validation-warnings: [Computed dataset percentiles naively by averaging
          percentiles of samples., 'Model tensorflow version (1, 15) does not match
          1.14.0.The prediction results may be wrong', 'Device management is not implemented
          for keras yet, cannot unload model']
