bioimageio_core_version: 0.5.3.post2
bioimageio_spec_version: 0.4.5.post13
rdf_sha256: 7a6002923c5aa5eaf2f61ff2849044a62fee325f4b2f4e3075ad2086ef00d505
status: passed
tests:
  bioimageio:
  - bioimageio_spec_version: 0.4.5post13
    error: null
    name: bioimageio.spec static validation of model RDF 0.4.5 with update to latest
      format version
    nested_errors: {}
    status: passed
    traceback: null
    warnings: {license: BSD-2-Clause (BSD 2-Clause "Simplified" License) is not FSF
        Free/libre., tags: 'Missing tags for categories: [{''modality'': [''electron-microscopy'',
        ''cryo-electron-microscopy'', ''fluorescence-light-microscopy'', ''transmission-light-microscopy'',
        ''super-resolution-microscopy'', ''x-ray-microscopy'', ''force-microscopy'',
        ''high-content-imaging'', ''whole-slide-imaging'', ''other'']}, {''content'':
        [''cells'', ''nuclei'', ''extracellular-vesicles'', ''tissue'', ''plant'',
        ''mitochondria'', ''vasculature'', ''cell-membrane'', ''brain'', ''whole-organism'']},
        {''task'': [''semantic-segmentation'', ''instance-segmentation'', ''object-detection'',
        ''image-classification'', ''denoising'', ''image-restoration'', ''image-reconstruction'',
        ''in-silico-labeling'']}]'}
  - bioimageio_spec_version: 0.4.5post13
    error: null
    name: bioimageio.spec static validation of model RDF 0.4.5
    nested_errors: {}
    status: passed
    traceback: null
    warnings: {license: BSD-2-Clause (BSD 2-Clause "Simplified" License) is not FSF
        Free/libre., tags: 'Missing tags for categories: [{''modality'': [''electron-microscopy'',
        ''cryo-electron-microscopy'', ''fluorescence-light-microscopy'', ''transmission-light-microscopy'',
        ''super-resolution-microscopy'', ''x-ray-microscopy'', ''force-microscopy'',
        ''high-content-imaging'', ''whole-slide-imaging'', ''other'']}, {''content'':
        [''cells'', ''nuclei'', ''extracellular-vesicles'', ''tissue'', ''plant'',
        ''mitochondria'', ''vasculature'', ''cell-membrane'', ''brain'', ''whole-organism'']},
        {''task'': [''semantic-segmentation'', ''instance-segmentation'', ''object-detection'',
        ''image-classification'', ''denoising'', ''image-restoration'', ''image-reconstruction'',
        ''in-silico-labeling'']}]'}
  - {bioimageio_core_version: 0.5.3post2, bioimageio_spec_version: 0.4.5post13, error: null,
    name: reproduced test outputs from test inputs, status: passed, traceback: null}
  deepimagej:
  - bioimageio_core_version: 0.5.3post2
    bioimageio_spec_version: 0.4.5post7
    error: '[Errno 2] No such file or directory: ''/home/runner/work/models/models/bioimageio-gh-pages/rdfs/10.5281/zenodo.5914248/5914249/exampleImage.npy'''
    name: reproduce test outputs with deepimagej 2.1.13 using tensorflow_saved_model_bundle
      weights
    reason: error
    status: failed
    traceback: ["  File \"/home/runner/work/models/models/scripts/check_rdf_and_test_model.py\",
        line 97, in test_resource\n    inputs = [np.load(str(in_path)) for in_path
        in model.test_inputs]\n", "  File \"/home/runner/work/models/models/scripts/check_rdf_and_test_model.py\",
        line 97, in <listcomp>\n    inputs = [np.load(str(in_path)) for in_path in
        model.test_inputs]\n", "  File \"/usr/share/miniconda3/envs/deepImageJEnv/lib/python3.8/site-packages/numpy/lib/npyio.py\",
        line 407, in load\n    fid = stack.enter_context(open(os_fspath(file), \"rb\"))\n"]
  - bioimageio_core_version: 0.5.3post2
    bioimageio_spec_version: 0.4.5post7
    error: '[Errno 2] No such file or directory: ''/home/runner/work/models/models/bioimageio-gh-pages/rdfs/10.5281/zenodo.5914248/5914249/exampleImage.npy'''
    name: reproduce test outputs with deepimagej 2.1.13 using keras_hdf5 weights
    reason: error
    status: failed
    traceback: ["  File \"/home/runner/work/models/models/scripts/check_rdf_and_test_model.py\",
        line 97, in test_resource\n    inputs = [np.load(str(in_path)) for in_path
        in model.test_inputs]\n", "  File \"/home/runner/work/models/models/scripts/check_rdf_and_test_model.py\",
        line 97, in <listcomp>\n    inputs = [np.load(str(in_path)) for in_path in
        model.test_inputs]\n", "  File \"/usr/share/miniconda3/envs/deepImageJEnv/lib/python3.8/site-packages/numpy/lib/npyio.py\",
        line 407, in load\n    fid = stack.enter_context(open(os_fspath(file), \"rb\"))\n"]
  ilastik:
  - bioimageio_core_version: 0.5.1
    bioimageio_spec_version: 0.4.5post3
    error: '''str'' object has no attribute ''decode'''
    name: reproduce test outputs with ilastik 1.4.0b26 using keras_hdf5 weights
    reason: error
    status: failed
    traceback: ["  File \"/usr/share/miniconda3/envs/ilastik-env/lib/python3.7/site-packages/bioimageio/core/resource_tests.py\",
        line 148, in test_resource\n    bioimageio_model=model, devices=devices, weight_format=weight_format\n",
      "  File \"/usr/share/miniconda3/envs/ilastik-env/lib/python3.7/site-packages/bioimageio/core/prediction_pipeline/_prediction_pipeline.py\",
        line 103, in __enter__\n    self.load()\n", "  File \"/usr/share/miniconda3/envs/ilastik-env/lib/python3.7/site-packages/bioimageio/core/prediction_pipeline/_prediction_pipeline.py\",
        line 143, in load\n    self._model.load()\n", "  File \"/usr/share/miniconda3/envs/ilastik-env/lib/python3.7/site-packages/bioimageio/core/prediction_pipeline/_model_adapters/_model_adapter.py\",
        line 41, in load\n    self._load(devices=devices or self.default_devices)\n",
      "  File \"/usr/share/miniconda3/envs/ilastik-env/lib/python3.7/site-packages/bioimageio/core/prediction_pipeline/_model_adapters/_keras_model_adapter.py\",
        line 39, in _load\n    self._model = keras.models.load_model(weight_file)\n",
      "  File \"/usr/share/miniconda3/envs/ilastik-env/lib/python3.7/site-packages/tensorflow/python/keras/saving/save.py\",
        line 146, in load_model\n    return hdf5_format.load_model_from_hdf5(filepath,
        custom_objects, compile)\n", "  File \"/usr/share/miniconda3/envs/ilastik-env/lib/python3.7/site-packages/tensorflow/python/keras/saving/hdf5_format.py\",
        line 210, in load_model_from_hdf5\n    model_config = json.loads(model_config.decode('utf-8'))\n"]
  - {bioimageio_core_version: 0.5.3post2, bioimageio_spec_version: 0.4.5post6, error: null,
    name: reproduce test outputs with ilastik 1.4.0b27 using tensorflow_saved_model_bundle
      weights, reason: null, status: passed, traceback: null}
  - bioimageio_core_version: 0.5.3post2
    bioimageio_spec_version: 0.4.5post6
    error: '''str'' object has no attribute ''decode'''
    name: reproduce test outputs with ilastik 1.4.0b27 using keras_hdf5 weights
    reason: error
    status: failed
    traceback: ["  File \"/usr/share/miniconda3/envs/ilastik-env/lib/python3.7/site-packages/bioimageio/core/resource_tests.py\",
        line 148, in test_resource\n    bioimageio_model=model, devices=devices, weight_format=weight_format\n",
      "  File \"/usr/share/miniconda3/envs/ilastik-env/lib/python3.7/site-packages/bioimageio/core/prediction_pipeline/_prediction_pipeline.py\",
        line 114, in __enter__\n    self.load()\n", "  File \"/usr/share/miniconda3/envs/ilastik-env/lib/python3.7/site-packages/bioimageio/core/prediction_pipeline/_prediction_pipeline.py\",
        line 172, in load\n    self._model.load()\n", "  File \"/usr/share/miniconda3/envs/ilastik-env/lib/python3.7/site-packages/bioimageio/core/prediction_pipeline/_model_adapters/_model_adapter.py\",
        line 41, in load\n    self._load(devices=devices or self.default_devices)\n",
      "  File \"/usr/share/miniconda3/envs/ilastik-env/lib/python3.7/site-packages/bioimageio/core/prediction_pipeline/_model_adapters/_keras_model_adapter.py\",
        line 41, in _load\n    self._model = keras.models.load_model(weight_file)\n",
      "  File \"/usr/share/miniconda3/envs/ilastik-env/lib/python3.7/site-packages/tensorflow/python/keras/saving/save.py\",
        line 146, in load_model\n    return hdf5_format.load_model_from_hdf5(filepath,
        custom_objects, compile)\n", "  File \"/usr/share/miniconda3/envs/ilastik-env/lib/python3.7/site-packages/tensorflow/python/keras/saving/hdf5_format.py\",
        line 210, in load_model_from_hdf5\n    model_config = json.loads(model_config.decode('utf-8'))\n"]
  - {error: Missing/invalid weight formats for 10.5281/zenodo.5914248/5914249, name: reproduce
      test outputs with ilastik 1.4.0b26, reason: error, status: failed}
  - {bioimageio_core_version: 0.5.1, bioimageio_spec_version: 0.4.5post3, error: null,
    name: reproduce test outputs with ilastik 1.4.0b26 using tensorflow_saved_model_bundle
      weights, reason: null, status: passed, traceback: null}
  - {error: Missing/invalid weight formats for 10.5281/zenodo.5914248/5914249, name: reproduce
      test outputs with ilastik 1.4.0b27, reason: error, status: failed}
