bioimageio_core_version: 0.5.9
bioimageio_spec_version: 0.4.9
rdf_sha256: be7248f2ed72a80f691e1f04f332a56a5856103653e146108cea8fad200218f3
status: passed
tests:
  bioimageio:
  - bioimageio_spec_version: 0.4.9
    error: null
    name: bioimageio.spec static validation of model RDF 0.4.9 with update to latest
      format version
    nested_errors: {}
    status: passed
    traceback: null
    warnings: {}
  - bioimageio_spec_version: 0.4.9
    error: null
    name: bioimageio.spec static validation of model RDF 0.4.9
    nested_errors: {}
    status: passed
    traceback: null
    warnings: {}
  - bioimageio_core_version: 0.5.9
    bioimageio_spec_version: 0.4.9
    error: null
    name: load resource description
    nested_errors: null
    status: passed
    traceback: null
    warnings: {}
  - bioimageio_core_version: 0.5.9
    bioimageio_spec_version: 0.4.9
    error: null
    name: All URLs and paths available
    nested_errors: null
    status: passed
    traceback: null
    warnings: {}
  - bioimageio_core_version: 0.5.9
    bioimageio_spec_version: 0.4.9
    error: null
    name: Test documentation completeness.
    status: passed
    traceback: null
    warnings: {documentation: No '# Validation' (sub)section found.}
  - bioimageio_core_version: 0.5.9
    bioimageio_spec_version: 0.4.9
    error: null
    name: reproduce test outputs from test inputs (bioimageio.core 0.5.9)
    status: passed
    traceback: null
    warnings:
      non-validation-warnings: [Computed dataset percentiles naively by averaging
          percentiles of samples., 'Device management is not implemented for keras
          yet, cannot unload model']
  deepimagej:
  - {bioimageio_spec_version: 0.4.8post1, error: Error while running DeepImageJ headless
      (CI did not produce an output image), name: Reproduce test outputs with DeepImageJ
      headless, status: failed}
  ilastik:
  - bioimageio_core_version: 0.5.7
    bioimageio_spec_version: 0.4.8
    error: null
    name: load resource description
    status: passed
    traceback: null
    warnings: {}
  - {error: null, name: has expected resource type, status: passed, traceback: null}
  - bioimageio_core_version: 0.5.7
    bioimageio_spec_version: 0.4.8
    error: null
    name: All URLs and paths available
    nested_errors: null
    status: passed
    traceback: null
    warnings: {}
  - bioimageio_core_version: 0.5.7
    bioimageio_spec_version: 0.4.8
    error: null
    name: Test documentation completeness.
    status: passed
    traceback: null
    warnings: {documentation: No '# Validation' (sub)section found.}
  - bioimageio_core_version: 0.5.7
    bioimageio_spec_version: 0.4.8
    error: The name '' looks like an (invalid) Operation name, not a Tensor. Tensor
      names must be of the form "<op_name>:<output_index>".
    name: reproduce test outputs from test inputs
    status: failed
    traceback: ["  File \"/usr/share/miniconda3/envs/ilastik-env/lib/python3.7/site-packages/bioimageio/core/resource_tests.py\",
        line 159, in _test_model_inference\n    results = predict(prediction_pipeline,
        inputs)\n", "  File \"/usr/share/miniconda3/envs/ilastik-env/lib/python3.7/site-packages/bioimageio/core/prediction.py\",
        line 150, in predict\n    return prediction_pipeline.forward(*tagged_data)\n",
      "  File \"/usr/share/miniconda3/envs/ilastik-env/lib/python3.7/site-packages/bioimageio/core/prediction_pipeline/_prediction_pipeline.py\",
        line 173, in forward\n    prediction_tensors = self.predict(*list(input_sample.values()))\n",
      "  File \"/usr/share/miniconda3/envs/ilastik-env/lib/python3.7/site-packages/bioimageio/core/prediction_pipeline/_prediction_pipeline.py\",
        line 143, in predict\n    return self._model.forward(*input_tensors)\n", "  File
        \"/usr/share/miniconda3/envs/ilastik-env/lib/python3.7/site-packages/bioimageio/core/prediction_pipeline/_model_adapters/_model_adapter.py\",
        line 75, in forward\n    return self._forward(*input_tensors)\n", "  File
        \"/usr/share/miniconda3/envs/ilastik-env/lib/python3.7/site-packages/bioimageio/core/prediction_pipeline/_model_adapters/_tensorflow_model_adapter.py\",
        line 118, in _forward\n    result = self._forward_tf(*data)\n", "  File \"/usr/share/miniconda3/envs/ilastik-env/lib/python3.7/site-packages/bioimageio/core/prediction_pipeline/_model_adapters/_tensorflow_model_adapter.py\",
        line 90, in _forward_tf\n    in_tensors = [graph.get_tensor_by_name(name)
        for name in in_names]\n", "  File \"/usr/share/miniconda3/envs/ilastik-env/lib/python3.7/site-packages/bioimageio/core/prediction_pipeline/_model_adapters/_tensorflow_model_adapter.py\",
        line 90, in <listcomp>\n    in_tensors = [graph.get_tensor_by_name(name) for
        name in in_names]\n", "  File \"/usr/share/miniconda3/envs/ilastik-env/lib/python3.7/site-packages/tensorflow/python/framework/ops.py\",
        line 3972, in get_tensor_by_name\n    return self.as_graph_element(name, allow_tensor=True,
        allow_operation=False)\n", "  File \"/usr/share/miniconda3/envs/ilastik-env/lib/python3.7/site-packages/tensorflow/python/framework/ops.py\",
        line 3796, in as_graph_element\n    return self._as_graph_element_locked(obj,
        allow_tensor, allow_operation)\n", "  File \"/usr/share/miniconda3/envs/ilastik-env/lib/python3.7/site-packages/tensorflow/python/framework/ops.py\",
        line 3870, in _as_graph_element_locked\n    raise ValueError(err_msg)\n"]
    warnings:
      non-validation-warnings: ['Device management is not implemented for keras yet,
          cannot unload model', Computed dataset percentiles naively by averaging
          percentiles of samples., 'Model tensorflow version (2, 11) does not match
          1.14.0.The prediction results may be wrong']
  - bioimageio_core_version: 0.5.8
    bioimageio_spec_version: 0.4.9
    error: null
    name: load resource description
    nested_errors: null
    status: passed
    traceback: null
    warnings: {}
  - bioimageio_core_version: 0.5.8
    bioimageio_spec_version: 0.4.9
    error: null
    name: All URLs and paths available
    nested_errors: null
    status: passed
    traceback: null
    warnings: {}
  - bioimageio_core_version: 0.5.8
    bioimageio_spec_version: 0.4.9
    error: null
    name: Test documentation completeness.
    status: passed
    traceback: null
    warnings: {documentation: No '# Validation' (sub)section found.}
  - bioimageio_core_version: 0.5.8
    bioimageio_spec_version: 0.4.9
    error: The name '' looks like an (invalid) Operation name, not a Tensor. Tensor
      names must be of the form "<op_name>:<output_index>".
    name: reproduce test outputs from test inputs
    status: failed
    traceback: ["  File \"/usr/share/miniconda3/envs/ilastik-env/lib/python3.7/site-packages/bioimageio/core/resource_tests.py\",
        line 159, in _test_model_inference\n    results = predict(prediction_pipeline,
        inputs)\n", "  File \"/usr/share/miniconda3/envs/ilastik-env/lib/python3.7/site-packages/bioimageio/core/prediction.py\",
        line 164, in predict\n    return prediction_pipeline.forward(*tagged_data)\n",
      "  File \"/usr/share/miniconda3/envs/ilastik-env/lib/python3.7/site-packages/bioimageio/core/prediction_pipeline/_prediction_pipeline.py\",
        line 173, in forward\n    prediction_tensors = self.predict(*list(input_sample.values()))\n",
      "  File \"/usr/share/miniconda3/envs/ilastik-env/lib/python3.7/site-packages/bioimageio/core/prediction_pipeline/_prediction_pipeline.py\",
        line 143, in predict\n    return self._model.forward(*input_tensors)\n", "  File
        \"/usr/share/miniconda3/envs/ilastik-env/lib/python3.7/site-packages/bioimageio/core/prediction_pipeline/_model_adapters/_model_adapter.py\",
        line 75, in forward\n    return self._forward(*input_tensors)\n", "  File
        \"/usr/share/miniconda3/envs/ilastik-env/lib/python3.7/site-packages/bioimageio/core/prediction_pipeline/_model_adapters/_tensorflow_model_adapter.py\",
        line 118, in _forward\n    result = self._forward_tf(*data)\n", "  File \"/usr/share/miniconda3/envs/ilastik-env/lib/python3.7/site-packages/bioimageio/core/prediction_pipeline/_model_adapters/_tensorflow_model_adapter.py\",
        line 90, in _forward_tf\n    in_tensors = [graph.get_tensor_by_name(name)
        for name in in_names]\n", "  File \"/usr/share/miniconda3/envs/ilastik-env/lib/python3.7/site-packages/bioimageio/core/prediction_pipeline/_model_adapters/_tensorflow_model_adapter.py\",
        line 90, in <listcomp>\n    in_tensors = [graph.get_tensor_by_name(name) for
        name in in_names]\n", "  File \"/usr/share/miniconda3/envs/ilastik-env/lib/python3.7/site-packages/tensorflow/python/framework/ops.py\",
        line 3972, in get_tensor_by_name\n    return self.as_graph_element(name, allow_tensor=True,
        allow_operation=False)\n", "  File \"/usr/share/miniconda3/envs/ilastik-env/lib/python3.7/site-packages/tensorflow/python/framework/ops.py\",
        line 3796, in as_graph_element\n    return self._as_graph_element_locked(obj,
        allow_tensor, allow_operation)\n", "  File \"/usr/share/miniconda3/envs/ilastik-env/lib/python3.7/site-packages/tensorflow/python/framework/ops.py\",
        line 3870, in _as_graph_element_locked\n    raise ValueError(err_msg)\n"]
    warnings:
      non-validation-warnings: ['Model tensorflow version (2, 11) does not match 1.14.0.The
          prediction results may be wrong', 'Device management is not implemented
          for keras yet, cannot unload model', Computed dataset percentiles naively
          by averaging percentiles of samples.]
  - bioimageio_core_version: 0.5.8
    bioimageio_spec_version: 0.4.9
    error: '''str'' object has no attribute ''decode'''
    name: reproduce test outputs from test inputs
    status: failed
    traceback: ["  File \"/usr/share/miniconda3/envs/ilastik-env/lib/python3.7/site-packages/bioimageio/core/resource_tests.py\",
        line 157, in _test_model_inference\n    bioimageio_model=model, devices=devices,
        weight_format=weight_format\n", "  File \"/usr/share/miniconda3/envs/ilastik-env/lib/python3.7/site-packages/bioimageio/core/prediction_pipeline/_prediction_pipeline.py\",
        line 122, in __enter__\n    self.load()\n", "  File \"/usr/share/miniconda3/envs/ilastik-env/lib/python3.7/site-packages/bioimageio/core/prediction_pipeline/_prediction_pipeline.py\",
        line 180, in load\n    self._model.load()\n", "  File \"/usr/share/miniconda3/envs/ilastik-env/lib/python3.7/site-packages/bioimageio/core/prediction_pipeline/_model_adapters/_model_adapter.py\",
        line 57, in load\n    self._load(devices=devices or self.default_devices)\n",
      "  File \"/usr/share/miniconda3/envs/ilastik-env/lib/python3.7/site-packages/bioimageio/core/prediction_pipeline/_model_adapters/_keras_model_adapter.py\",
        line 41, in _load\n    self._model = keras.models.load_model(weight_file)\n",
      "  File \"/usr/share/miniconda3/envs/ilastik-env/lib/python3.7/site-packages/tensorflow/python/keras/saving/save.py\",
        line 146, in load_model\n    return hdf5_format.load_model_from_hdf5(filepath,
        custom_objects, compile)\n", "  File \"/usr/share/miniconda3/envs/ilastik-env/lib/python3.7/site-packages/tensorflow/python/keras/saving/hdf5_format.py\",
        line 210, in load_model_from_hdf5\n    model_config = json.loads(model_config.decode('utf-8'))\n"]
    warnings:
      non-validation-warnings: ['Model tensorflow version (2, 11) does not match 1.14.0.The
          prediction results may be wrong']
  - bioimageio_core_version: 0.5.7
    bioimageio_spec_version: 0.4.8
    error: '''str'' object has no attribute ''decode'''
    name: reproduce test outputs from test inputs
    status: failed
    traceback: ["  File \"/usr/share/miniconda3/envs/ilastik-env/lib/python3.7/site-packages/bioimageio/core/resource_tests.py\",
        line 157, in _test_model_inference\n    bioimageio_model=model, devices=devices,
        weight_format=weight_format\n", "  File \"/usr/share/miniconda3/envs/ilastik-env/lib/python3.7/site-packages/bioimageio/core/prediction_pipeline/_prediction_pipeline.py\",
        line 122, in __enter__\n    self.load()\n", "  File \"/usr/share/miniconda3/envs/ilastik-env/lib/python3.7/site-packages/bioimageio/core/prediction_pipeline/_prediction_pipeline.py\",
        line 180, in load\n    self._model.load()\n", "  File \"/usr/share/miniconda3/envs/ilastik-env/lib/python3.7/site-packages/bioimageio/core/prediction_pipeline/_model_adapters/_model_adapter.py\",
        line 57, in load\n    self._load(devices=devices or self.default_devices)\n",
      "  File \"/usr/share/miniconda3/envs/ilastik-env/lib/python3.7/site-packages/bioimageio/core/prediction_pipeline/_model_adapters/_keras_model_adapter.py\",
        line 41, in _load\n    self._model = keras.models.load_model(weight_file)\n",
      "  File \"/usr/share/miniconda3/envs/ilastik-env/lib/python3.7/site-packages/tensorflow/python/keras/saving/save.py\",
        line 146, in load_model\n    return hdf5_format.load_model_from_hdf5(filepath,
        custom_objects, compile)\n", "  File \"/usr/share/miniconda3/envs/ilastik-env/lib/python3.7/site-packages/tensorflow/python/keras/saving/hdf5_format.py\",
        line 210, in load_model_from_hdf5\n    model_config = json.loads(model_config.decode('utf-8'))\n"]
    warnings:
      non-validation-warnings: ['Model tensorflow version (2, 11) does not match 1.14.0.The
          prediction results may be wrong']
