bioimageio_core_version: 0.5.8
bioimageio_spec_version: 0.4.9
rdf_sha256: 0d58fefd626ee8e71b5d2e2413282fd38a2a7b031b71fb8509398f52619dcf8f
status: failed
tests:
  bioimageio:
  - bioimageio_spec_version: 0.4.9
    error: null
    name: bioimageio.spec static validation of model RDF 0.4.9 with update to latest
      format version
    nested_errors: {}
    status: passed
    traceback: null
    warnings: {cite: missing, tags: 'Missing tags corresponding to bioimage.io categories:
        [{''software'': [''ilastik'', ''imagej'', ''fiji'', ''imjoy'', ''deepimagej'',
        ''n2v'']}]'}
  - bioimageio_spec_version: 0.4.9
    error: null
    name: bioimageio.spec static validation of model RDF 0.4.9
    nested_errors: {}
    status: passed
    traceback: null
    warnings: {cite: missing, tags: 'Missing tags corresponding to bioimage.io categories:
        [{''software'': [''ilastik'', ''imagej'', ''fiji'', ''imjoy'', ''deepimagej'',
        ''n2v'']}]'}
  - bioimageio_core_version: 0.5.8
    bioimageio_spec_version: 0.4.9
    error: null
    name: load resource description
    nested_errors: null
    status: passed
    traceback: null
    warnings: {}
  - bioimageio_core_version: 0.5.8
    bioimageio_spec_version: 0.4.9
    error: https://bioimage-io.github.io/collection-bioimage-io/rdfs/10.5281/zenodo.7380171/7405349/rdf.yaml
    name: All URLs and paths available
    nested_errors: null
    status: failed
    traceback: ["  File \"/home/runner/micromamba-root/envs/7405349/lib/python3.10/site-packages/bioimageio/core/resource_tests.py\",
        line 87, in _test_resource_urls\n    SourceNodeChecker(root_path=rd.root_path).visit(rd)\n",
      "  File \"/home/runner/micromamba-root/envs/7405349/lib/python3.10/site-packages/bioimageio/spec/shared/node_transformer.py\",
        line 34, in visit\n    visitor(node)\n", "  File \"/home/runner/micromamba-root/envs/7405349/lib/python3.10/site-packages/bioimageio/core/resource_io/utils.py\",
        line 52, in generic_visit\n    self.visit(value)\n", "  File \"/home/runner/micromamba-root/envs/7405349/lib/python3.10/site-packages/bioimageio/spec/shared/node_transformer.py\",
        line 34, in visit\n    visitor(node)\n", "  File \"/home/runner/micromamba-root/envs/7405349/lib/python3.10/site-packages/bioimageio/core/resource_io/utils.py\",
        line 38, in visit_URI\n    self._visit_source(node)\n", "  File \"/home/runner/micromamba-root/envs/7405349/lib/python3.10/site-packages/bioimageio/core/resource_io/utils.py\",
        line 35, in _visit_source\n    raise FileNotFoundError(leaf)\n"]
    warnings: {}
  - bioimageio_core_version: 0.5.8
    bioimageio_spec_version: 0.4.9
    error: null
    name: Test documentation completeness.
    status: passed
    traceback: null
    warnings: {documentation: No '# Validation' (sub)section found.}
  - bioimageio_core_version: 0.5.8
    bioimageio_spec_version: 0.4.9
    error: null
    name: reproduce test outputs from test inputs
    status: passed
    traceback: null
    warnings:
      non-validation-warnings: ['Device management is not implemented for keras yet,
          cannot unload model']
  deepimagej:
  - {bioimageio_spec_version: 0.4.8post1, error: 'rdf does not have keys for :config
      :deepimagej', name: Initial compatibility checks with DeepImageJ, status: failed}
  ilastik:
  - bioimageio_core_version: 0.5.7
    bioimageio_spec_version: 0.4.8
    error: null
    name: load resource description
    status: passed
    traceback: null
    warnings: {}
  - {error: null, name: has expected resource type, status: passed, traceback: null}
  - bioimageio_core_version: 0.5.7
    bioimageio_spec_version: 0.4.8
    error: null
    name: All URLs and paths available
    nested_errors: null
    status: passed
    traceback: null
    warnings: {}
  - bioimageio_core_version: 0.5.7
    bioimageio_spec_version: 0.4.8
    error: null
    name: Test documentation completeness.
    status: passed
    traceback: null
    warnings: {documentation: No '# Validation' (sub)section found.}
  - bioimageio_core_version: 0.5.7
    bioimageio_spec_version: 0.4.8
    error: The name '' looks like an (invalid) Operation name, not a Tensor. Tensor
      names must be of the form "<op_name>:<output_index>".
    name: reproduce test outputs from test inputs
    status: failed
    traceback: ["  File \"/usr/share/miniconda3/envs/ilastik-env/lib/python3.7/site-packages/bioimageio/core/resource_tests.py\",
        line 159, in _test_model_inference\n    results = predict(prediction_pipeline,
        inputs)\n", "  File \"/usr/share/miniconda3/envs/ilastik-env/lib/python3.7/site-packages/bioimageio/core/prediction.py\",
        line 150, in predict\n    return prediction_pipeline.forward(*tagged_data)\n",
      "  File \"/usr/share/miniconda3/envs/ilastik-env/lib/python3.7/site-packages/bioimageio/core/prediction_pipeline/_prediction_pipeline.py\",
        line 173, in forward\n    prediction_tensors = self.predict(*list(input_sample.values()))\n",
      "  File \"/usr/share/miniconda3/envs/ilastik-env/lib/python3.7/site-packages/bioimageio/core/prediction_pipeline/_prediction_pipeline.py\",
        line 143, in predict\n    return self._model.forward(*input_tensors)\n", "  File
        \"/usr/share/miniconda3/envs/ilastik-env/lib/python3.7/site-packages/bioimageio/core/prediction_pipeline/_model_adapters/_model_adapter.py\",
        line 75, in forward\n    return self._forward(*input_tensors)\n", "  File
        \"/usr/share/miniconda3/envs/ilastik-env/lib/python3.7/site-packages/bioimageio/core/prediction_pipeline/_model_adapters/_tensorflow_model_adapter.py\",
        line 118, in _forward\n    result = self._forward_tf(*data)\n", "  File \"/usr/share/miniconda3/envs/ilastik-env/lib/python3.7/site-packages/bioimageio/core/prediction_pipeline/_model_adapters/_tensorflow_model_adapter.py\",
        line 90, in _forward_tf\n    in_tensors = [graph.get_tensor_by_name(name)
        for name in in_names]\n", "  File \"/usr/share/miniconda3/envs/ilastik-env/lib/python3.7/site-packages/bioimageio/core/prediction_pipeline/_model_adapters/_tensorflow_model_adapter.py\",
        line 90, in <listcomp>\n    in_tensors = [graph.get_tensor_by_name(name) for
        name in in_names]\n", "  File \"/usr/share/miniconda3/envs/ilastik-env/lib/python3.7/site-packages/tensorflow/python/framework/ops.py\",
        line 3972, in get_tensor_by_name\n    return self.as_graph_element(name, allow_tensor=True,
        allow_operation=False)\n", "  File \"/usr/share/miniconda3/envs/ilastik-env/lib/python3.7/site-packages/tensorflow/python/framework/ops.py\",
        line 3796, in as_graph_element\n    return self._as_graph_element_locked(obj,
        allow_tensor, allow_operation)\n", "  File \"/usr/share/miniconda3/envs/ilastik-env/lib/python3.7/site-packages/tensorflow/python/framework/ops.py\",
        line 3870, in _as_graph_element_locked\n    raise ValueError(err_msg)\n"]
    warnings:
      non-validation-warnings: ['Device management is not implemented for keras yet,
          cannot unload model', 'Model tensorflow version (2, 10) does not match 1.14.0.The
          prediction results may be wrong']
  - bioimageio_core_version: 0.5.8
    bioimageio_spec_version: 0.4.9
    error: null
    name: All URLs and paths available
    nested_errors: null
    status: passed
    traceback: null
    warnings: {}
  - bioimageio_core_version: 0.5.8
    bioimageio_spec_version: 0.4.9
    error: The name '' looks like an (invalid) Operation name, not a Tensor. Tensor
      names must be of the form "<op_name>:<output_index>".
    name: reproduce test outputs from test inputs
    status: failed
    traceback: ["  File \"/usr/share/miniconda3/envs/ilastik-env/lib/python3.7/site-packages/bioimageio/core/resource_tests.py\",
        line 159, in _test_model_inference\n    results = predict(prediction_pipeline,
        inputs)\n", "  File \"/usr/share/miniconda3/envs/ilastik-env/lib/python3.7/site-packages/bioimageio/core/prediction.py\",
        line 164, in predict\n    return prediction_pipeline.forward(*tagged_data)\n",
      "  File \"/usr/share/miniconda3/envs/ilastik-env/lib/python3.7/site-packages/bioimageio/core/prediction_pipeline/_prediction_pipeline.py\",
        line 173, in forward\n    prediction_tensors = self.predict(*list(input_sample.values()))\n",
      "  File \"/usr/share/miniconda3/envs/ilastik-env/lib/python3.7/site-packages/bioimageio/core/prediction_pipeline/_prediction_pipeline.py\",
        line 143, in predict\n    return self._model.forward(*input_tensors)\n", "  File
        \"/usr/share/miniconda3/envs/ilastik-env/lib/python3.7/site-packages/bioimageio/core/prediction_pipeline/_model_adapters/_model_adapter.py\",
        line 75, in forward\n    return self._forward(*input_tensors)\n", "  File
        \"/usr/share/miniconda3/envs/ilastik-env/lib/python3.7/site-packages/bioimageio/core/prediction_pipeline/_model_adapters/_tensorflow_model_adapter.py\",
        line 118, in _forward\n    result = self._forward_tf(*data)\n", "  File \"/usr/share/miniconda3/envs/ilastik-env/lib/python3.7/site-packages/bioimageio/core/prediction_pipeline/_model_adapters/_tensorflow_model_adapter.py\",
        line 90, in _forward_tf\n    in_tensors = [graph.get_tensor_by_name(name)
        for name in in_names]\n", "  File \"/usr/share/miniconda3/envs/ilastik-env/lib/python3.7/site-packages/bioimageio/core/prediction_pipeline/_model_adapters/_tensorflow_model_adapter.py\",
        line 90, in <listcomp>\n    in_tensors = [graph.get_tensor_by_name(name) for
        name in in_names]\n", "  File \"/usr/share/miniconda3/envs/ilastik-env/lib/python3.7/site-packages/tensorflow/python/framework/ops.py\",
        line 3972, in get_tensor_by_name\n    return self.as_graph_element(name, allow_tensor=True,
        allow_operation=False)\n", "  File \"/usr/share/miniconda3/envs/ilastik-env/lib/python3.7/site-packages/tensorflow/python/framework/ops.py\",
        line 3796, in as_graph_element\n    return self._as_graph_element_locked(obj,
        allow_tensor, allow_operation)\n", "  File \"/usr/share/miniconda3/envs/ilastik-env/lib/python3.7/site-packages/tensorflow/python/framework/ops.py\",
        line 3870, in _as_graph_element_locked\n    raise ValueError(err_msg)\n"]
    warnings:
      non-validation-warnings: ['Model tensorflow version (2, 10) does not match 1.14.0.The
          prediction results may be wrong', 'Device management is not implemented
          for keras yet, cannot unload model']
