rdf_sha256: 0e2650d43589a193642f1bf0bb04d18bb046fa0cf8872f115d136e7b4eba7f6f
tests:
  deepimagej:
  - bioimageio_core_version: 0.5.3post2
    bioimageio_spec_version: 0.4.5post7
    error: '{''_schema'': [''Referenced tensor input_images with 3 dimensions does
      not match output tensor output_images with 4 dimensions.'']}'
    name: reproduce test outputs with deepimagej 2.1.13 using tensorflow_saved_model_bundle
      weights
    reason: error
    status: failed
    traceback: ["  File \"/home/runner/work/models/models/scripts/check_rdf_and_test_model.py\",
        line 45, in test_model\n    model = load_resource_description(\n", "  File
        \"/usr/share/miniconda3/envs/deepImageJEnv/lib/python3.8/site-packages/bioimageio/core/resource_io/io_.py\",
        line 47, in load_resource_description\n    raw_rd = load_raw_resource_description(source,
        update_to_format=\"latest\")\n", "  File \"/usr/share/miniconda3/envs/deepImageJEnv/lib/python3.8/site-packages/bioimageio/spec/io_.py\",
        line 197, in load_raw_resource_description\n    raw_rd = schema.load(data)\n",
      "  File \"/usr/share/miniconda3/envs/deepImageJEnv/lib/python3.8/site-packages/marshmallow/schema.py\",
        line 717, in load\n    return self._do_load(\n", "  File \"/usr/share/miniconda3/envs/deepImageJEnv/lib/python3.8/site-packages/marshmallow/schema.py\",
        line 900, in _do_load\n    raise exc\n"]
  - {error: Missing/invalid weight formats for deepimagej/WidefieldDapiSuperResolution/latest,
    name: reproduce test outputs with deepimagej 2.1.13, reason: error, status: failed}
  ilastik:
  - {error: Missing/invalid weight formats for deepimagej/WidefieldDapiSuperResolution/latest,
    name: reproduce test outputs with ilastik <todo version> (draft), reason: error,
    status: failed}
  - bioimageio_core_version: 0.5.3post2
    bioimageio_spec_version: 0.4.5post6
    error: '{''_schema'': [''Referenced tensor input_images with 3 dimensions does
      not match output tensor output_images with 4 dimensions.'']}'
    name: reproduce test outputs with ilastik 1.4.0b27 using tensorflow_saved_model_bundle
      weights
    reason: error
    status: failed
    traceback: ["  File \"/usr/share/miniconda3/envs/ilastik-env/lib/python3.7/site-packages/bioimageio/core/resource_tests.py\",
        line 39, in test_model\n    model_rdf, weights_priority_order=None if weight_format
        is None else [weight_format]\n", "  File \"/usr/share/miniconda3/envs/ilastik-env/lib/python3.7/site-packages/bioimageio/core/resource_io/io_.py\",
        line 47, in load_resource_description\n    raw_rd = load_raw_resource_description(source,
        update_to_format=\"latest\")\n", "  File \"/usr/share/miniconda3/envs/ilastik-env/lib/python3.7/site-packages/bioimageio/spec/io_.py\",
        line 197, in load_raw_resource_description\n    raw_rd = schema.load(data)\n",
      "  File \"/usr/share/miniconda3/envs/ilastik-env/lib/python3.7/site-packages/marshmallow/schema.py\",
        line 718, in load\n    data, many=many, partial=partial, unknown=unknown,
        postprocess=True\n", "  File \"/usr/share/miniconda3/envs/ilastik-env/lib/python3.7/site-packages/marshmallow/schema.py\",
        line 900, in _do_load\n    raise exc\n"]
  - bioimageio_core_version: 0.5.1
    bioimageio_spec_version: 0.4.5post3
    error: '{''_schema'': [''Referenced tensor input_images with 3 dimensions does
      not match output tensor output_images with 4 dimensions.'']}'
    name: reproduce test outputs with ilastik 1.4.0b26 using tensorflow_saved_model_bundle
      weights
    reason: error
    status: failed
    traceback: ["  File \"/usr/share/miniconda3/envs/ilastik-env/lib/python3.7/site-packages/bioimageio/core/resource_tests.py\",
        line 39, in test_model\n    model_rdf, weights_priority_order=None if weight_format
        is None else [weight_format]\n", "  File \"/usr/share/miniconda3/envs/ilastik-env/lib/python3.7/site-packages/bioimageio/core/resource_io/io_.py\",
        line 41, in load_resource_description\n    raw_rd = load_raw_resource_description(source,
        update_to_format=\"latest\")\n", "  File \"/usr/share/miniconda3/envs/ilastik-env/lib/python3.7/site-packages/bioimageio/spec/io_.py\",
        line 191, in load_raw_resource_description\n    raw_rd = schema.load(data)\n",
      "  File \"/usr/share/miniconda3/envs/ilastik-env/lib/python3.7/site-packages/marshmallow/schema.py\",
        line 718, in load\n    data, many=many, partial=partial, unknown=unknown,
        postprocess=True\n", "  File \"/usr/share/miniconda3/envs/ilastik-env/lib/python3.7/site-packages/marshmallow/schema.py\",
        line 900, in _do_load\n    raise exc\n"]
  - {error: Missing/invalid weight formats for deepimagej/WidefieldDapiSuperResolution/latest,
    name: reproduce test outputs with ilastik <todo version> (draft), reason: error,
    status: failed}
